{
    "id": "problem_195",
    "description": "\n\nThe problem is a RuntimeError that occurs when attempting to access a DefaultDict with an invalid key. The error occurs because the DefaultDict does not contain the specified key and thus cannot return its associated value.",
    "output": "Traceback (most recent call last):\n  File \"<stdin>\", line 1, in <module>\nTypeError: 'dict' object is not callable",
    "tags": [
        "RuntimeError",
        "DefaultDict",
        "Hard"
    ]
}