{
    "id": "problem_139",
    "description": "\n\nWhen running a Python script, an AttributeError is raised when attempting to access the sys.config attribute. This is due to the sys module not having a config attribute, and the script attempting to access it without first checking its existence.",
    "output": "Traceback (most recent call last):\n  File \"<stdin>\", line 2, in <module>\nAttributeError: module 'sys' has no attribute 'config'",
    "tags": [
        "AttributeError",
        "sys",
        "Easy"
    ]
}